<mujoco model="partnet_3317da004c4177a5f47e82e63eafd5bc-0">
    <!-- Compiler Options -->
    <compiler angle="radian" coordinate="local" />

    <!-- Simulation Options -->
    <option gravity="0 0 -9.81" />

    <!-- Asset Definitions -->
    <asset>
        <!-- Mesh Assets -->
        <mesh name="textured_objs_original_11" file="original-11.obj" />
        <mesh name="textured_objs_original_12" file="original-12.obj" />
        <mesh name="textured_objs_original_14" file="original-14.obj" />
        <mesh name="textured_objs_original_15" file="original-15.obj" />
        <mesh name="textured_objs_original_17" file="original-17.obj" />
        <mesh name="textured_objs_original_18" file="original-18.obj" />
        <mesh name="textured_objs_original_2" file="original-2.obj" />
        <mesh name="textured_objs_original_3" file="original-3.obj" />
        <mesh name="textured_objs_original_5" file="original-5.obj" />
        <mesh name="textured_objs_original_6" file="original-6.obj" />
        <mesh name="textured_objs_original_8" file="original-8.obj" />
        <mesh name="textured_objs_original_9" file="original-9.obj" />
    </asset>

    <!-- World Body -->
    <worldbody>
        <!-- Base Body -->
        <body name="base">
            <!-- Joint joint_2: fixed connecting base -> link_2 -->
            <body name="link_2" pos="0.0 0.0 0.0" euler="1.570796326794897 0.0 -1.570796326794897">
                <geom type="mesh" mesh="textured_objs_original_5" pos="0.0 0.0 0.0" />
                <geom type="mesh" mesh="textured_objs_original_6" pos="0.0 0.0 0.0" />
                <geom type="mesh" mesh="textured_objs_original_15" pos="0.0 0.0 0.0" />
                <geom type="mesh" mesh="textured_objs_original_11" pos="0.0 0.0 0.0" />
                <geom type="mesh" mesh="textured_objs_original_18" pos="0.0 0.0 0.0" />
                <geom type="mesh" mesh="textured_objs_original_17" pos="0.0 0.0 0.0" />
                <geom type="mesh" mesh="textured_objs_original_12" pos="0.0 0.0 0.0" />
                <geom type="mesh" mesh="textured_objs_original_14" pos="0.0 0.0 0.0" />
                <!-- Joint joint_0: revolute connecting link_2 -> link_0 -->
                <body name="link_0" pos="0.31660425872202214 0.29751199999999994 -0.24250700000000014" euler="0.0 0.0 0.0">
                    <joint name="joint_0" type="hinge" axis="-0.9659262867695628 0.0 0.0" range="-1.832595714594046 1.2915436464758039" />
                    <geom type="mesh" mesh="textured_objs_original_9" pos="-0.31660425872202214 -0.29751199999999994 0.24250700000000014" />
                    <geom type="mesh" mesh="textured_objs_original_8" pos="-0.31660425872202214 -0.29751199999999994 0.24250700000000014" />
                </body>
                <!-- Joint joint_1: prismatic connecting link_2 -> link_1 -->
                <body name="link_1" pos="-0.46159568235906356 -0.21526026863272418 0.284856" euler="0.0 0.0 0.0">
                    <joint name="joint_1" type="slide" axis="0.0 0.0 0.9999999999999999" range="-0.25 0.19199999999999995" />
                    <geom type="mesh" mesh="textured_objs_original_2" pos="0.46159568235906356 0.21526026863272418 -0.284856" />
                    <geom type="mesh" mesh="textured_objs_original_3" pos="0.46159568235906356 0.21526026863272418 -0.284856" />
                </body>
            </body>
        </body>
    </worldbody>
</mujoco>
